[2022-12-25T04:42:43.455+0000] {taskinstance.py:1087} INFO - Dependencies all met for <TaskInstance: test_etl_deps.etl_test manual__2022-12-25T04:40:36.590248+00:00 [queued]>
[2022-12-25T04:42:43.492+0000] {taskinstance.py:1087} INFO - Dependencies all met for <TaskInstance: test_etl_deps.etl_test manual__2022-12-25T04:40:36.590248+00:00 [queued]>
[2022-12-25T04:42:43.495+0000] {taskinstance.py:1283} INFO - 
--------------------------------------------------------------------------------
[2022-12-25T04:42:43.498+0000] {taskinstance.py:1284} INFO - Starting attempt 2 of 6
[2022-12-25T04:42:43.500+0000] {taskinstance.py:1285} INFO - 
--------------------------------------------------------------------------------
[2022-12-25T04:42:43.530+0000] {taskinstance.py:1304} INFO - Executing <Task(BashOperator): etl_test> on 2022-12-25 04:40:36.590248+00:00
[2022-12-25T04:42:43.541+0000] {standard_task_runner.py:55} INFO - Started process 3096 to run task
[2022-12-25T04:42:43.553+0000] {standard_task_runner.py:82} INFO - Running: ['***', 'tasks', 'run', 'test_etl_deps', 'etl_test', 'manual__2022-12-25T04:40:36.590248+00:00', '--job-id', '158', '--raw', '--subdir', 'DAGS_FOLDER/test_etl_deps.py', '--cfg-path', '/tmp/tmpsgzmfcf2']
[2022-12-25T04:42:43.557+0000] {standard_task_runner.py:83} INFO - Job 158: Subtask etl_test
[2022-12-25T04:42:43.724+0000] {task_command.py:389} INFO - Running <TaskInstance: test_etl_deps.etl_test manual__2022-12-25T04:40:36.590248+00:00 [running]> on host 176142c05a95
[2022-12-25T04:42:43.881+0000] {taskinstance.py:1513} INFO - Exporting the following env vars:
AIRFLOW_CTX_DAG_OWNER=kelompok2
AIRFLOW_CTX_DAG_ID=test_etl_deps
AIRFLOW_CTX_TASK_ID=etl_test
AIRFLOW_CTX_EXECUTION_DATE=2022-12-25T04:40:36.590248+00:00
AIRFLOW_CTX_TRY_NUMBER=2
AIRFLOW_CTX_DAG_RUN_ID=manual__2022-12-25T04:40:36.590248+00:00
[2022-12-25T04:42:43.889+0000] {subprocess.py:63} INFO - Tmp dir root location: 
 /tmp
[2022-12-25T04:42:43.893+0000] {subprocess.py:75} INFO - Running command: ['/bin/bash', '-c', 'tree']
[2022-12-25T04:42:43.927+0000] {subprocess.py:86} INFO - Output:
[2022-12-25T04:42:43.935+0000] {subprocess.py:93} INFO - /bin/bash: line 1: tree: command not found
[2022-12-25T04:42:43.938+0000] {subprocess.py:97} INFO - Command exited with return code 127
[2022-12-25T04:42:43.963+0000] {taskinstance.py:1772} ERROR - Task failed with exception
Traceback (most recent call last):
  File "/home/airflow/.local/lib/python3.7/site-packages/airflow/operators/bash.py", line 197, in execute
    f"Bash command failed. The command returned a non-zero exit code {result.exit_code}."
airflow.exceptions.AirflowException: Bash command failed. The command returned a non-zero exit code 127.
[2022-12-25T04:42:43.975+0000] {taskinstance.py:1327} INFO - Marking task as UP_FOR_RETRY. dag_id=test_etl_deps, task_id=etl_test, execution_date=20221225T044036, start_date=20221225T044243, end_date=20221225T044243
[2022-12-25T04:42:44.005+0000] {standard_task_runner.py:105} ERROR - Failed to execute job 158 for task etl_test (Bash command failed. The command returned a non-zero exit code 127.; 3096)
[2022-12-25T04:42:44.053+0000] {local_task_job.py:159} INFO - Task exited with return code 1
[2022-12-25T04:42:44.100+0000] {taskinstance.py:2582} INFO - 0 downstream tasks scheduled from follow-on schedule check
