[2022-12-25T04:19:59.656+0000] {taskinstance.py:1087} INFO - Dependencies all met for <TaskInstance: test_etl_deps.etl_test manual__2022-12-25T04:13:51.889791+00:00 [queued]>
[2022-12-25T04:19:59.666+0000] {taskinstance.py:1087} INFO - Dependencies all met for <TaskInstance: test_etl_deps.etl_test manual__2022-12-25T04:13:51.889791+00:00 [queued]>
[2022-12-25T04:19:59.668+0000] {taskinstance.py:1283} INFO - 
--------------------------------------------------------------------------------
[2022-12-25T04:19:59.670+0000] {taskinstance.py:1284} INFO - Starting attempt 4 of 6
[2022-12-25T04:19:59.671+0000] {taskinstance.py:1285} INFO - 
--------------------------------------------------------------------------------
[2022-12-25T04:19:59.686+0000] {taskinstance.py:1304} INFO - Executing <Task(BashOperator): etl_test> on 2022-12-25 04:13:51.889791+00:00
[2022-12-25T04:19:59.694+0000] {standard_task_runner.py:55} INFO - Started process 1603 to run task
[2022-12-25T04:19:59.700+0000] {standard_task_runner.py:82} INFO - Running: ['***', 'tasks', 'run', 'test_etl_deps', 'etl_test', 'manual__2022-12-25T04:13:51.889791+00:00', '--job-id', '113', '--raw', '--subdir', 'DAGS_FOLDER/test_etl_deps.py', '--cfg-path', '/tmp/tmp06xr2pgb']
[2022-12-25T04:19:59.703+0000] {standard_task_runner.py:83} INFO - Job 113: Subtask etl_test
[2022-12-25T04:19:59.786+0000] {task_command.py:389} INFO - Running <TaskInstance: test_etl_deps.etl_test manual__2022-12-25T04:13:51.889791+00:00 [running]> on host 176142c05a95
[2022-12-25T04:19:59.879+0000] {taskinstance.py:1513} INFO - Exporting the following env vars:
AIRFLOW_CTX_DAG_OWNER=kelompok2
AIRFLOW_CTX_DAG_ID=test_etl_deps
AIRFLOW_CTX_TASK_ID=etl_test
AIRFLOW_CTX_EXECUTION_DATE=2022-12-25T04:13:51.889791+00:00
AIRFLOW_CTX_TRY_NUMBER=4
AIRFLOW_CTX_DAG_RUN_ID=manual__2022-12-25T04:13:51.889791+00:00
[2022-12-25T04:19:59.885+0000] {subprocess.py:63} INFO - Tmp dir root location: 
 /tmp
[2022-12-25T04:19:59.890+0000] {subprocess.py:75} INFO - Running command: ['/bin/bash', '-c', 'python ~/scripts/consumer.py']
[2022-12-25T04:19:59.910+0000] {subprocess.py:86} INFO - Output:
[2022-12-25T04:20:00.031+0000] {subprocess.py:93} INFO - python: can't open file '/home/***/scripts/consumer.py': [Errno 2] No such file or directory
[2022-12-25T04:20:00.037+0000] {subprocess.py:97} INFO - Command exited with return code 2
[2022-12-25T04:20:00.060+0000] {taskinstance.py:1772} ERROR - Task failed with exception
Traceback (most recent call last):
  File "/home/airflow/.local/lib/python3.7/site-packages/airflow/operators/bash.py", line 197, in execute
    f"Bash command failed. The command returned a non-zero exit code {result.exit_code}."
airflow.exceptions.AirflowException: Bash command failed. The command returned a non-zero exit code 2.
[2022-12-25T04:20:00.068+0000] {taskinstance.py:1327} INFO - Marking task as UP_FOR_RETRY. dag_id=test_etl_deps, task_id=etl_test, execution_date=20221225T041351, start_date=20221225T041959, end_date=20221225T042000
[2022-12-25T04:20:00.089+0000] {standard_task_runner.py:105} ERROR - Failed to execute job 113 for task etl_test (Bash command failed. The command returned a non-zero exit code 2.; 1603)
[2022-12-25T04:20:00.117+0000] {local_task_job.py:159} INFO - Task exited with return code 1
[2022-12-25T04:20:00.154+0000] {taskinstance.py:2582} INFO - 0 downstream tasks scheduled from follow-on schedule check
