[2022-12-25T04:08:51.679+0000] {taskinstance.py:1087} INFO - Dependencies all met for <TaskInstance: test_etl_deps.etl_test manual__2022-12-25T04:08:50.436097+00:00 [queued]>
[2022-12-25T04:08:51.691+0000] {taskinstance.py:1087} INFO - Dependencies all met for <TaskInstance: test_etl_deps.etl_test manual__2022-12-25T04:08:50.436097+00:00 [queued]>
[2022-12-25T04:08:51.692+0000] {taskinstance.py:1283} INFO - 
--------------------------------------------------------------------------------
[2022-12-25T04:08:51.693+0000] {taskinstance.py:1284} INFO - Starting attempt 1 of 6
[2022-12-25T04:08:51.695+0000] {taskinstance.py:1285} INFO - 
--------------------------------------------------------------------------------
[2022-12-25T04:08:51.713+0000] {taskinstance.py:1304} INFO - Executing <Task(BashOperator): etl_test> on 2022-12-25 04:08:50.436097+00:00
[2022-12-25T04:08:51.721+0000] {standard_task_runner.py:55} INFO - Started process 849 to run task
[2022-12-25T04:08:51.729+0000] {standard_task_runner.py:82} INFO - Running: ['***', 'tasks', 'run', 'test_etl_deps', 'etl_test', 'manual__2022-12-25T04:08:50.436097+00:00', '--job-id', '91', '--raw', '--subdir', 'DAGS_FOLDER/test_etl_deps.py', '--cfg-path', '/tmp/tmp7yj12xgd']
[2022-12-25T04:08:51.733+0000] {standard_task_runner.py:83} INFO - Job 91: Subtask etl_test
[2022-12-25T04:08:51.863+0000] {task_command.py:389} INFO - Running <TaskInstance: test_etl_deps.etl_test manual__2022-12-25T04:08:50.436097+00:00 [running]> on host 176142c05a95
[2022-12-25T04:08:51.984+0000] {taskinstance.py:1513} INFO - Exporting the following env vars:
AIRFLOW_CTX_DAG_OWNER=kelompok2
AIRFLOW_CTX_DAG_ID=test_etl_deps
AIRFLOW_CTX_TASK_ID=etl_test
AIRFLOW_CTX_EXECUTION_DATE=2022-12-25T04:08:50.436097+00:00
AIRFLOW_CTX_TRY_NUMBER=1
AIRFLOW_CTX_DAG_RUN_ID=manual__2022-12-25T04:08:50.436097+00:00
[2022-12-25T04:08:51.990+0000] {subprocess.py:63} INFO - Tmp dir root location: 
 /tmp
[2022-12-25T04:08:51.995+0000] {subprocess.py:75} INFO - Running command: ['/bin/bash', '-c', 'python python/consumer.py']
[2022-12-25T04:08:52.019+0000] {subprocess.py:86} INFO - Output:
[2022-12-25T04:08:52.183+0000] {subprocess.py:93} INFO - python: can't open file 'python/consumer.py': [Errno 2] No such file or directory
[2022-12-25T04:08:52.188+0000] {subprocess.py:97} INFO - Command exited with return code 2
[2022-12-25T04:08:52.208+0000] {taskinstance.py:1772} ERROR - Task failed with exception
Traceback (most recent call last):
  File "/home/airflow/.local/lib/python3.7/site-packages/airflow/operators/bash.py", line 197, in execute
    f"Bash command failed. The command returned a non-zero exit code {result.exit_code}."
airflow.exceptions.AirflowException: Bash command failed. The command returned a non-zero exit code 2.
[2022-12-25T04:08:52.216+0000] {taskinstance.py:1327} INFO - Marking task as UP_FOR_RETRY. dag_id=test_etl_deps, task_id=etl_test, execution_date=20221225T040850, start_date=20221225T040851, end_date=20221225T040852
[2022-12-25T04:08:52.235+0000] {standard_task_runner.py:105} ERROR - Failed to execute job 91 for task etl_test (Bash command failed. The command returned a non-zero exit code 2.; 849)
[2022-12-25T04:08:52.270+0000] {local_task_job.py:159} INFO - Task exited with return code 1
[2022-12-25T04:08:52.381+0000] {taskinstance.py:2582} INFO - 0 downstream tasks scheduled from follow-on schedule check
