[2022-12-25T04:31:05.573+0000] {taskinstance.py:1087} INFO - Dependencies all met for <TaskInstance: test_etl_deps.py_test manual__2022-12-25T04:21:44.986828+00:00 [queued]>
[2022-12-25T04:31:05.582+0000] {taskinstance.py:1087} INFO - Dependencies all met for <TaskInstance: test_etl_deps.py_test manual__2022-12-25T04:21:44.986828+00:00 [queued]>
[2022-12-25T04:31:05.584+0000] {taskinstance.py:1283} INFO - 
--------------------------------------------------------------------------------
[2022-12-25T04:31:05.585+0000] {taskinstance.py:1284} INFO - Starting attempt 2 of 6
[2022-12-25T04:31:05.587+0000] {taskinstance.py:1285} INFO - 
--------------------------------------------------------------------------------
[2022-12-25T04:31:05.600+0000] {taskinstance.py:1304} INFO - Executing <Task(BashOperator): py_test> on 2022-12-25 04:21:44.986828+00:00
[2022-12-25T04:31:05.606+0000] {standard_task_runner.py:55} INFO - Started process 2357 to run task
[2022-12-25T04:31:05.611+0000] {standard_task_runner.py:82} INFO - Running: ['***', 'tasks', 'run', 'test_etl_deps', 'py_test', 'manual__2022-12-25T04:21:44.986828+00:00', '--job-id', '134', '--raw', '--subdir', 'DAGS_FOLDER/test_etl_deps.py', '--cfg-path', '/tmp/tmpyt13n9vk']
[2022-12-25T04:31:05.613+0000] {standard_task_runner.py:83} INFO - Job 134: Subtask py_test
[2022-12-25T04:31:05.678+0000] {task_command.py:389} INFO - Running <TaskInstance: test_etl_deps.py_test manual__2022-12-25T04:21:44.986828+00:00 [running]> on host 176142c05a95
[2022-12-25T04:31:05.787+0000] {taskinstance.py:1513} INFO - Exporting the following env vars:
AIRFLOW_CTX_DAG_OWNER=kelompok2
AIRFLOW_CTX_DAG_ID=test_etl_deps
AIRFLOW_CTX_TASK_ID=py_test
AIRFLOW_CTX_EXECUTION_DATE=2022-12-25T04:21:44.986828+00:00
AIRFLOW_CTX_TRY_NUMBER=2
AIRFLOW_CTX_DAG_RUN_ID=manual__2022-12-25T04:21:44.986828+00:00
[2022-12-25T04:31:05.791+0000] {subprocess.py:63} INFO - Tmp dir root location: 
 /tmp
[2022-12-25T04:31:05.793+0000] {subprocess.py:75} INFO - Running command: ['/bin/bash', '-c', 'python3 scripts/consumer.py']
[2022-12-25T04:31:05.814+0000] {subprocess.py:86} INFO - Output:
[2022-12-25T04:31:05.960+0000] {subprocess.py:93} INFO - python3: can't open file 'scripts/consumer.py': [Errno 2] No such file or directory
[2022-12-25T04:31:05.964+0000] {subprocess.py:97} INFO - Command exited with return code 2
[2022-12-25T04:31:05.987+0000] {taskinstance.py:1772} ERROR - Task failed with exception
Traceback (most recent call last):
  File "/home/airflow/.local/lib/python3.7/site-packages/airflow/operators/bash.py", line 197, in execute
    f"Bash command failed. The command returned a non-zero exit code {result.exit_code}."
airflow.exceptions.AirflowException: Bash command failed. The command returned a non-zero exit code 2.
[2022-12-25T04:31:05.995+0000] {taskinstance.py:1327} INFO - Marking task as UP_FOR_RETRY. dag_id=test_etl_deps, task_id=py_test, execution_date=20221225T042144, start_date=20221225T043105, end_date=20221225T043105
[2022-12-25T04:31:06.021+0000] {standard_task_runner.py:105} ERROR - Failed to execute job 134 for task py_test (Bash command failed. The command returned a non-zero exit code 2.; 2357)
[2022-12-25T04:31:06.067+0000] {local_task_job.py:159} INFO - Task exited with return code 1
[2022-12-25T04:31:06.093+0000] {taskinstance.py:2582} INFO - 0 downstream tasks scheduled from follow-on schedule check
