[2022-12-25T04:05:16.676+0000] {taskinstance.py:1087} INFO - Dependencies all met for <TaskInstance: test_etl_deps.etl_test manual__2022-12-25T04:05:14.776420+00:00 [queued]>
[2022-12-25T04:05:16.689+0000] {taskinstance.py:1087} INFO - Dependencies all met for <TaskInstance: test_etl_deps.etl_test manual__2022-12-25T04:05:14.776420+00:00 [queued]>
[2022-12-25T04:05:16.691+0000] {taskinstance.py:1283} INFO - 
--------------------------------------------------------------------------------
[2022-12-25T04:05:16.693+0000] {taskinstance.py:1284} INFO - Starting attempt 1 of 6
[2022-12-25T04:05:16.695+0000] {taskinstance.py:1285} INFO - 
--------------------------------------------------------------------------------
[2022-12-25T04:05:16.717+0000] {taskinstance.py:1304} INFO - Executing <Task(BashOperator): etl_test> on 2022-12-25 04:05:14.776420+00:00
[2022-12-25T04:05:16.733+0000] {standard_task_runner.py:55} INFO - Started process 618 to run task
[2022-12-25T04:05:16.740+0000] {standard_task_runner.py:82} INFO - Running: ['***', 'tasks', 'run', 'test_etl_deps', 'etl_test', 'manual__2022-12-25T04:05:14.776420+00:00', '--job-id', '88', '--raw', '--subdir', 'DAGS_FOLDER/test_etl_deps.py', '--cfg-path', '/tmp/tmpo2x2yq8y']
[2022-12-25T04:05:16.744+0000] {standard_task_runner.py:83} INFO - Job 88: Subtask etl_test
[2022-12-25T04:05:16.851+0000] {task_command.py:389} INFO - Running <TaskInstance: test_etl_deps.etl_test manual__2022-12-25T04:05:14.776420+00:00 [running]> on host 176142c05a95
[2022-12-25T04:05:16.968+0000] {taskinstance.py:1513} INFO - Exporting the following env vars:
AIRFLOW_CTX_DAG_OWNER=kelompok2
AIRFLOW_CTX_DAG_ID=test_etl_deps
AIRFLOW_CTX_TASK_ID=etl_test
AIRFLOW_CTX_EXECUTION_DATE=2022-12-25T04:05:14.776420+00:00
AIRFLOW_CTX_TRY_NUMBER=1
AIRFLOW_CTX_DAG_RUN_ID=manual__2022-12-25T04:05:14.776420+00:00
[2022-12-25T04:05:16.973+0000] {subprocess.py:63} INFO - Tmp dir root location: 
 /tmp
[2022-12-25T04:05:16.976+0000] {subprocess.py:75} INFO - Running command: ['/bin/bash', '-c', 'cd ..\n\npython python/consumer.py']
[2022-12-25T04:05:16.998+0000] {subprocess.py:86} INFO - Output:
[2022-12-25T04:05:17.132+0000] {subprocess.py:93} INFO - python: can't open file 'python/consumer.py': [Errno 2] No such file or directory
[2022-12-25T04:05:17.137+0000] {subprocess.py:97} INFO - Command exited with return code 2
[2022-12-25T04:05:17.155+0000] {taskinstance.py:1772} ERROR - Task failed with exception
Traceback (most recent call last):
  File "/home/airflow/.local/lib/python3.7/site-packages/airflow/operators/bash.py", line 197, in execute
    f"Bash command failed. The command returned a non-zero exit code {result.exit_code}."
airflow.exceptions.AirflowException: Bash command failed. The command returned a non-zero exit code 2.
[2022-12-25T04:05:17.165+0000] {taskinstance.py:1327} INFO - Marking task as UP_FOR_RETRY. dag_id=test_etl_deps, task_id=etl_test, execution_date=20221225T040514, start_date=20221225T040516, end_date=20221225T040517
[2022-12-25T04:05:17.188+0000] {standard_task_runner.py:105} ERROR - Failed to execute job 88 for task etl_test (Bash command failed. The command returned a non-zero exit code 2.; 618)
[2022-12-25T04:05:17.237+0000] {local_task_job.py:159} INFO - Task exited with return code 1
[2022-12-25T04:05:17.265+0000] {taskinstance.py:2582} INFO - 0 downstream tasks scheduled from follow-on schedule check
