[2022-12-25T04:17:03.429+0000] {taskinstance.py:1087} INFO - Dependencies all met for <TaskInstance: test_etl_deps.etl_test manual__2022-12-25T04:14:57.146211+00:00 [queued]>
[2022-12-25T04:17:03.442+0000] {taskinstance.py:1087} INFO - Dependencies all met for <TaskInstance: test_etl_deps.etl_test manual__2022-12-25T04:14:57.146211+00:00 [queued]>
[2022-12-25T04:17:03.445+0000] {taskinstance.py:1283} INFO - 
--------------------------------------------------------------------------------
[2022-12-25T04:17:03.446+0000] {taskinstance.py:1284} INFO - Starting attempt 2 of 6
[2022-12-25T04:17:03.448+0000] {taskinstance.py:1285} INFO - 
--------------------------------------------------------------------------------
[2022-12-25T04:17:03.466+0000] {taskinstance.py:1304} INFO - Executing <Task(BashOperator): etl_test> on 2022-12-25 04:14:57.146211+00:00
[2022-12-25T04:17:03.475+0000] {standard_task_runner.py:55} INFO - Started process 1395 to run task
[2022-12-25T04:17:03.480+0000] {standard_task_runner.py:82} INFO - Running: ['***', 'tasks', 'run', 'test_etl_deps', 'etl_test', 'manual__2022-12-25T04:14:57.146211+00:00', '--job-id', '104', '--raw', '--subdir', 'DAGS_FOLDER/test_etl_deps.py', '--cfg-path', '/tmp/tmpxnxh1_l2']
[2022-12-25T04:17:03.484+0000] {standard_task_runner.py:83} INFO - Job 104: Subtask etl_test
[2022-12-25T04:17:03.590+0000] {task_command.py:389} INFO - Running <TaskInstance: test_etl_deps.etl_test manual__2022-12-25T04:14:57.146211+00:00 [running]> on host 176142c05a95
[2022-12-25T04:17:03.699+0000] {taskinstance.py:1513} INFO - Exporting the following env vars:
AIRFLOW_CTX_DAG_OWNER=kelompok2
AIRFLOW_CTX_DAG_ID=test_etl_deps
AIRFLOW_CTX_TASK_ID=etl_test
AIRFLOW_CTX_EXECUTION_DATE=2022-12-25T04:14:57.146211+00:00
AIRFLOW_CTX_TRY_NUMBER=2
AIRFLOW_CTX_DAG_RUN_ID=manual__2022-12-25T04:14:57.146211+00:00
[2022-12-25T04:17:03.705+0000] {subprocess.py:63} INFO - Tmp dir root location: 
 /tmp
[2022-12-25T04:17:03.708+0000] {subprocess.py:75} INFO - Running command: ['/bin/bash', '-c', 'python ~/scripts/consumer.py']
[2022-12-25T04:17:03.731+0000] {subprocess.py:86} INFO - Output:
[2022-12-25T04:17:03.853+0000] {subprocess.py:93} INFO - python: can't open file '/home/***/scripts/consumer.py': [Errno 2] No such file or directory
[2022-12-25T04:17:03.858+0000] {subprocess.py:97} INFO - Command exited with return code 2
[2022-12-25T04:17:03.876+0000] {taskinstance.py:1772} ERROR - Task failed with exception
Traceback (most recent call last):
  File "/home/airflow/.local/lib/python3.7/site-packages/airflow/operators/bash.py", line 197, in execute
    f"Bash command failed. The command returned a non-zero exit code {result.exit_code}."
airflow.exceptions.AirflowException: Bash command failed. The command returned a non-zero exit code 2.
[2022-12-25T04:17:03.883+0000] {taskinstance.py:1327} INFO - Marking task as UP_FOR_RETRY. dag_id=test_etl_deps, task_id=etl_test, execution_date=20221225T041457, start_date=20221225T041703, end_date=20221225T041703
[2022-12-25T04:17:03.908+0000] {standard_task_runner.py:105} ERROR - Failed to execute job 104 for task etl_test (Bash command failed. The command returned a non-zero exit code 2.; 1395)
[2022-12-25T04:17:03.950+0000] {local_task_job.py:159} INFO - Task exited with return code 1
[2022-12-25T04:17:03.971+0000] {taskinstance.py:2582} INFO - 0 downstream tasks scheduled from follow-on schedule check
