[2022-12-25T04:38:01.435+0000] {taskinstance.py:1087} INFO - Dependencies all met for <TaskInstance: test_etl_deps.py_test manual__2022-12-25T04:37:54.990081+00:00 [queued]>
[2022-12-25T04:38:01.533+0000] {taskinstance.py:1087} INFO - Dependencies all met for <TaskInstance: test_etl_deps.py_test manual__2022-12-25T04:37:54.990081+00:00 [queued]>
[2022-12-25T04:38:01.539+0000] {taskinstance.py:1283} INFO - 
--------------------------------------------------------------------------------
[2022-12-25T04:38:01.547+0000] {taskinstance.py:1284} INFO - Starting attempt 1 of 6
[2022-12-25T04:38:01.559+0000] {taskinstance.py:1285} INFO - 
--------------------------------------------------------------------------------
[2022-12-25T04:38:01.700+0000] {taskinstance.py:1304} INFO - Executing <Task(BashOperator): py_test> on 2022-12-25 04:37:54.990081+00:00
[2022-12-25T04:38:01.778+0000] {standard_task_runner.py:55} INFO - Started process 2800 to run task
[2022-12-25T04:38:01.804+0000] {standard_task_runner.py:82} INFO - Running: ['***', 'tasks', 'run', 'test_etl_deps', 'py_test', 'manual__2022-12-25T04:37:54.990081+00:00', '--job-id', '144', '--raw', '--subdir', 'DAGS_FOLDER/test_etl_deps.py', '--cfg-path', '/tmp/tmpj98l6w8p']
[2022-12-25T04:38:01.813+0000] {standard_task_runner.py:83} INFO - Job 144: Subtask py_test
[2022-12-25T04:38:02.282+0000] {task_command.py:389} INFO - Running <TaskInstance: test_etl_deps.py_test manual__2022-12-25T04:37:54.990081+00:00 [running]> on host 176142c05a95
[2022-12-25T04:38:02.729+0000] {taskinstance.py:1513} INFO - Exporting the following env vars:
AIRFLOW_CTX_DAG_OWNER=kelompok2
AIRFLOW_CTX_DAG_ID=test_etl_deps
AIRFLOW_CTX_TASK_ID=py_test
AIRFLOW_CTX_EXECUTION_DATE=2022-12-25T04:37:54.990081+00:00
AIRFLOW_CTX_TRY_NUMBER=1
AIRFLOW_CTX_DAG_RUN_ID=manual__2022-12-25T04:37:54.990081+00:00
[2022-12-25T04:38:02.746+0000] {subprocess.py:63} INFO - Tmp dir root location: 
 /tmp
[2022-12-25T04:38:02.755+0000] {subprocess.py:75} INFO - Running command: ['/bin/bash', '-c', 'python3 scripts/consumer.py']
[2022-12-25T04:38:02.815+0000] {subprocess.py:86} INFO - Output:
[2022-12-25T04:38:03.302+0000] {subprocess.py:93} INFO - python3: can't open file 'scripts/consumer.py': [Errno 2] No such file or directory
[2022-12-25T04:38:03.319+0000] {subprocess.py:97} INFO - Command exited with return code 2
[2022-12-25T04:38:03.370+0000] {taskinstance.py:1772} ERROR - Task failed with exception
Traceback (most recent call last):
  File "/home/airflow/.local/lib/python3.7/site-packages/airflow/operators/bash.py", line 197, in execute
    f"Bash command failed. The command returned a non-zero exit code {result.exit_code}."
airflow.exceptions.AirflowException: Bash command failed. The command returned a non-zero exit code 2.
[2022-12-25T04:38:03.398+0000] {taskinstance.py:1327} INFO - Marking task as UP_FOR_RETRY. dag_id=test_etl_deps, task_id=py_test, execution_date=20221225T043754, start_date=20221225T043801, end_date=20221225T043803
[2022-12-25T04:38:03.439+0000] {standard_task_runner.py:105} ERROR - Failed to execute job 144 for task py_test (Bash command failed. The command returned a non-zero exit code 2.; 2800)
[2022-12-25T04:38:03.524+0000] {local_task_job.py:159} INFO - Task exited with return code 1
[2022-12-25T04:38:03.619+0000] {taskinstance.py:2582} INFO - 0 downstream tasks scheduled from follow-on schedule check
