[2022-12-25T04:38:11.710+0000] {taskinstance.py:1087} INFO - Dependencies all met for <TaskInstance: test_etl_deps.py_test manual__2022-12-25T04:29:59.668002+00:00 [queued]>
[2022-12-25T04:38:11.761+0000] {taskinstance.py:1087} INFO - Dependencies all met for <TaskInstance: test_etl_deps.py_test manual__2022-12-25T04:29:59.668002+00:00 [queued]>
[2022-12-25T04:38:11.764+0000] {taskinstance.py:1283} INFO - 
--------------------------------------------------------------------------------
[2022-12-25T04:38:11.768+0000] {taskinstance.py:1284} INFO - Starting attempt 5 of 6
[2022-12-25T04:38:11.784+0000] {taskinstance.py:1285} INFO - 
--------------------------------------------------------------------------------
[2022-12-25T04:38:11.915+0000] {taskinstance.py:1304} INFO - Executing <Task(BashOperator): py_test> on 2022-12-25 04:29:59.668002+00:00
[2022-12-25T04:38:12.009+0000] {standard_task_runner.py:55} INFO - Started process 2816 to run task
[2022-12-25T04:38:12.142+0000] {standard_task_runner.py:82} INFO - Running: ['***', 'tasks', 'run', 'test_etl_deps', 'py_test', 'manual__2022-12-25T04:29:59.668002+00:00', '--job-id', '145', '--raw', '--subdir', 'DAGS_FOLDER/test_etl_deps.py', '--cfg-path', '/tmp/tmph77x9ish']
[2022-12-25T04:38:12.176+0000] {standard_task_runner.py:83} INFO - Job 145: Subtask py_test
[2022-12-25T04:38:12.684+0000] {task_command.py:389} INFO - Running <TaskInstance: test_etl_deps.py_test manual__2022-12-25T04:29:59.668002+00:00 [running]> on host 176142c05a95
[2022-12-25T04:38:13.266+0000] {taskinstance.py:1513} INFO - Exporting the following env vars:
AIRFLOW_CTX_DAG_OWNER=kelompok2
AIRFLOW_CTX_DAG_ID=test_etl_deps
AIRFLOW_CTX_TASK_ID=py_test
AIRFLOW_CTX_EXECUTION_DATE=2022-12-25T04:29:59.668002+00:00
AIRFLOW_CTX_TRY_NUMBER=5
AIRFLOW_CTX_DAG_RUN_ID=manual__2022-12-25T04:29:59.668002+00:00
[2022-12-25T04:38:13.282+0000] {subprocess.py:63} INFO - Tmp dir root location: 
 /tmp
[2022-12-25T04:38:13.294+0000] {subprocess.py:75} INFO - Running command: ['/bin/bash', '-c', 'python3 scripts/consumer.py']
[2022-12-25T04:38:13.355+0000] {subprocess.py:86} INFO - Output:
[2022-12-25T04:38:13.797+0000] {subprocess.py:93} INFO - python3: can't open file 'scripts/consumer.py': [Errno 2] No such file or directory
[2022-12-25T04:38:13.812+0000] {subprocess.py:97} INFO - Command exited with return code 2
[2022-12-25T04:38:13.904+0000] {taskinstance.py:1772} ERROR - Task failed with exception
Traceback (most recent call last):
  File "/home/airflow/.local/lib/python3.7/site-packages/airflow/operators/bash.py", line 197, in execute
    f"Bash command failed. The command returned a non-zero exit code {result.exit_code}."
airflow.exceptions.AirflowException: Bash command failed. The command returned a non-zero exit code 2.
[2022-12-25T04:38:13.928+0000] {taskinstance.py:1327} INFO - Marking task as UP_FOR_RETRY. dag_id=test_etl_deps, task_id=py_test, execution_date=20221225T042959, start_date=20221225T043811, end_date=20221225T043813
[2022-12-25T04:38:14.019+0000] {standard_task_runner.py:105} ERROR - Failed to execute job 145 for task py_test (Bash command failed. The command returned a non-zero exit code 2.; 2816)
[2022-12-25T04:38:14.109+0000] {local_task_job.py:159} INFO - Task exited with return code 1
[2022-12-25T04:38:14.255+0000] {taskinstance.py:2582} INFO - 0 downstream tasks scheduled from follow-on schedule check
