[2022-12-25T04:34:05.823+0000] {taskinstance.py:1087} INFO - Dependencies all met for <TaskInstance: test_etl_deps.py_test manual__2022-12-25T04:29:59.668002+00:00 [queued]>
[2022-12-25T04:34:05.841+0000] {taskinstance.py:1087} INFO - Dependencies all met for <TaskInstance: test_etl_deps.py_test manual__2022-12-25T04:29:59.668002+00:00 [queued]>
[2022-12-25T04:34:05.844+0000] {taskinstance.py:1283} INFO - 
--------------------------------------------------------------------------------
[2022-12-25T04:34:05.846+0000] {taskinstance.py:1284} INFO - Starting attempt 3 of 6
[2022-12-25T04:34:05.848+0000] {taskinstance.py:1285} INFO - 
--------------------------------------------------------------------------------
[2022-12-25T04:34:05.896+0000] {taskinstance.py:1304} INFO - Executing <Task(BashOperator): py_test> on 2022-12-25 04:29:59.668002+00:00
[2022-12-25T04:34:05.918+0000] {standard_task_runner.py:55} INFO - Started process 2537 to run task
[2022-12-25T04:34:05.930+0000] {standard_task_runner.py:82} INFO - Running: ['***', 'tasks', 'run', 'test_etl_deps', 'py_test', 'manual__2022-12-25T04:29:59.668002+00:00', '--job-id', '137', '--raw', '--subdir', 'DAGS_FOLDER/test_etl_deps.py', '--cfg-path', '/tmp/tmpfuyj6vq6']
[2022-12-25T04:34:05.934+0000] {standard_task_runner.py:83} INFO - Job 137: Subtask py_test
[2022-12-25T04:34:06.076+0000] {task_command.py:389} INFO - Running <TaskInstance: test_etl_deps.py_test manual__2022-12-25T04:29:59.668002+00:00 [running]> on host 176142c05a95
[2022-12-25T04:34:06.226+0000] {taskinstance.py:1513} INFO - Exporting the following env vars:
AIRFLOW_CTX_DAG_OWNER=kelompok2
AIRFLOW_CTX_DAG_ID=test_etl_deps
AIRFLOW_CTX_TASK_ID=py_test
AIRFLOW_CTX_EXECUTION_DATE=2022-12-25T04:29:59.668002+00:00
AIRFLOW_CTX_TRY_NUMBER=3
AIRFLOW_CTX_DAG_RUN_ID=manual__2022-12-25T04:29:59.668002+00:00
[2022-12-25T04:34:06.236+0000] {subprocess.py:63} INFO - Tmp dir root location: 
 /tmp
[2022-12-25T04:34:06.239+0000] {subprocess.py:75} INFO - Running command: ['/bin/bash', '-c', 'python3 scripts/consumer.py']
[2022-12-25T04:34:06.263+0000] {subprocess.py:86} INFO - Output:
[2022-12-25T04:34:06.723+0000] {subprocess.py:93} INFO - python3: can't open file 'scripts/consumer.py': [Errno 2] No such file or directory
[2022-12-25T04:34:06.739+0000] {subprocess.py:97} INFO - Command exited with return code 2
[2022-12-25T04:34:06.799+0000] {taskinstance.py:1772} ERROR - Task failed with exception
Traceback (most recent call last):
  File "/home/airflow/.local/lib/python3.7/site-packages/airflow/operators/bash.py", line 197, in execute
    f"Bash command failed. The command returned a non-zero exit code {result.exit_code}."
airflow.exceptions.AirflowException: Bash command failed. The command returned a non-zero exit code 2.
[2022-12-25T04:34:06.820+0000] {taskinstance.py:1327} INFO - Marking task as UP_FOR_RETRY. dag_id=test_etl_deps, task_id=py_test, execution_date=20221225T042959, start_date=20221225T043405, end_date=20221225T043406
[2022-12-25T04:34:06.897+0000] {standard_task_runner.py:105} ERROR - Failed to execute job 137 for task py_test (Bash command failed. The command returned a non-zero exit code 2.; 2537)
[2022-12-25T04:34:06.964+0000] {local_task_job.py:159} INFO - Task exited with return code 1
[2022-12-25T04:34:07.056+0000] {taskinstance.py:2582} INFO - 0 downstream tasks scheduled from follow-on schedule check
