[2022-12-25T04:50:22.106+0000] {taskinstance.py:1087} INFO - Dependencies all met for <TaskInstance: test_etl_deps.py_test manual__2022-12-25T04:40:01.261358+00:00 [queued]>
[2022-12-25T04:50:22.130+0000] {taskinstance.py:1087} INFO - Dependencies all met for <TaskInstance: test_etl_deps.py_test manual__2022-12-25T04:40:01.261358+00:00 [queued]>
[2022-12-25T04:50:22.132+0000] {taskinstance.py:1283} INFO - 
--------------------------------------------------------------------------------
[2022-12-25T04:50:22.133+0000] {taskinstance.py:1284} INFO - Starting attempt 6 of 6
[2022-12-25T04:50:22.135+0000] {taskinstance.py:1285} INFO - 
--------------------------------------------------------------------------------
[2022-12-25T04:50:22.156+0000] {taskinstance.py:1304} INFO - Executing <Task(BashOperator): py_test> on 2022-12-25 04:40:01.261358+00:00
[2022-12-25T04:50:22.165+0000] {standard_task_runner.py:55} INFO - Started process 3613 to run task
[2022-12-25T04:50:22.186+0000] {standard_task_runner.py:82} INFO - Running: ['***', 'tasks', 'run', 'test_etl_deps', 'py_test', 'manual__2022-12-25T04:40:01.261358+00:00', '--job-id', '175', '--raw', '--subdir', 'DAGS_FOLDER/test_etl_deps.py', '--cfg-path', '/tmp/tmpyfbd1f85']
[2022-12-25T04:50:22.189+0000] {standard_task_runner.py:83} INFO - Job 175: Subtask py_test
[2022-12-25T04:50:22.296+0000] {task_command.py:389} INFO - Running <TaskInstance: test_etl_deps.py_test manual__2022-12-25T04:40:01.261358+00:00 [running]> on host 176142c05a95
[2022-12-25T04:50:22.389+0000] {taskinstance.py:1513} INFO - Exporting the following env vars:
AIRFLOW_CTX_DAG_OWNER=kelompok2
AIRFLOW_CTX_DAG_ID=test_etl_deps
AIRFLOW_CTX_TASK_ID=py_test
AIRFLOW_CTX_EXECUTION_DATE=2022-12-25T04:40:01.261358+00:00
AIRFLOW_CTX_TRY_NUMBER=6
AIRFLOW_CTX_DAG_RUN_ID=manual__2022-12-25T04:40:01.261358+00:00
[2022-12-25T04:50:22.393+0000] {subprocess.py:63} INFO - Tmp dir root location: 
 /tmp
[2022-12-25T04:50:22.396+0000] {subprocess.py:75} INFO - Running command: ['/bin/bash', '-c', 'python3 scripts/consumer.py']
[2022-12-25T04:50:22.417+0000] {subprocess.py:86} INFO - Output:
[2022-12-25T04:50:22.612+0000] {subprocess.py:93} INFO - python3: can't open file 'scripts/consumer.py': [Errno 2] No such file or directory
[2022-12-25T04:50:22.622+0000] {subprocess.py:97} INFO - Command exited with return code 2
[2022-12-25T04:50:22.650+0000] {taskinstance.py:1772} ERROR - Task failed with exception
Traceback (most recent call last):
  File "/home/airflow/.local/lib/python3.7/site-packages/airflow/operators/bash.py", line 197, in execute
    f"Bash command failed. The command returned a non-zero exit code {result.exit_code}."
airflow.exceptions.AirflowException: Bash command failed. The command returned a non-zero exit code 2.
[2022-12-25T04:50:22.659+0000] {taskinstance.py:1327} INFO - Marking task as FAILED. dag_id=test_etl_deps, task_id=py_test, execution_date=20221225T044001, start_date=20221225T045022, end_date=20221225T045022
[2022-12-25T04:50:22.685+0000] {standard_task_runner.py:105} ERROR - Failed to execute job 175 for task py_test (Bash command failed. The command returned a non-zero exit code 2.; 3613)
[2022-12-25T04:50:22.736+0000] {local_task_job.py:159} INFO - Task exited with return code 1
[2022-12-25T04:50:22.767+0000] {taskinstance.py:2582} INFO - 0 downstream tasks scheduled from follow-on schedule check
