[2022-12-25T04:10:07.362+0000] {taskinstance.py:1087} INFO - Dependencies all met for <TaskInstance: test_etl_deps.etl_test manual__2022-12-25T04:08:03.500240+00:00 [queued]>
[2022-12-25T04:10:07.391+0000] {taskinstance.py:1087} INFO - Dependencies all met for <TaskInstance: test_etl_deps.etl_test manual__2022-12-25T04:08:03.500240+00:00 [queued]>
[2022-12-25T04:10:07.395+0000] {taskinstance.py:1283} INFO - 
--------------------------------------------------------------------------------
[2022-12-25T04:10:07.400+0000] {taskinstance.py:1284} INFO - Starting attempt 2 of 6
[2022-12-25T04:10:07.406+0000] {taskinstance.py:1285} INFO - 
--------------------------------------------------------------------------------
[2022-12-25T04:10:07.437+0000] {taskinstance.py:1304} INFO - Executing <Task(BashOperator): etl_test> on 2022-12-25 04:08:03.500240+00:00
[2022-12-25T04:10:07.452+0000] {standard_task_runner.py:55} INFO - Started process 936 to run task
[2022-12-25T04:10:07.461+0000] {standard_task_runner.py:82} INFO - Running: ['***', 'tasks', 'run', 'test_etl_deps', 'etl_test', 'manual__2022-12-25T04:08:03.500240+00:00', '--job-id', '92', '--raw', '--subdir', 'DAGS_FOLDER/test_etl_deps.py', '--cfg-path', '/tmp/tmpe03lrgai']
[2022-12-25T04:10:07.465+0000] {standard_task_runner.py:83} INFO - Job 92: Subtask etl_test
[2022-12-25T04:10:07.635+0000] {task_command.py:389} INFO - Running <TaskInstance: test_etl_deps.etl_test manual__2022-12-25T04:08:03.500240+00:00 [running]> on host 176142c05a95
[2022-12-25T04:10:07.819+0000] {taskinstance.py:1513} INFO - Exporting the following env vars:
AIRFLOW_CTX_DAG_OWNER=kelompok2
AIRFLOW_CTX_DAG_ID=test_etl_deps
AIRFLOW_CTX_TASK_ID=etl_test
AIRFLOW_CTX_EXECUTION_DATE=2022-12-25T04:08:03.500240+00:00
AIRFLOW_CTX_TRY_NUMBER=2
AIRFLOW_CTX_DAG_RUN_ID=manual__2022-12-25T04:08:03.500240+00:00
[2022-12-25T04:10:07.825+0000] {subprocess.py:63} INFO - Tmp dir root location: 
 /tmp
[2022-12-25T04:10:07.829+0000] {subprocess.py:75} INFO - Running command: ['/bin/bash', '-c', 'python python/consumer.py']
[2022-12-25T04:10:07.855+0000] {subprocess.py:86} INFO - Output:
[2022-12-25T04:10:08.038+0000] {subprocess.py:93} INFO - python: can't open file 'python/consumer.py': [Errno 2] No such file or directory
[2022-12-25T04:10:08.043+0000] {subprocess.py:97} INFO - Command exited with return code 2
[2022-12-25T04:10:08.067+0000] {taskinstance.py:1772} ERROR - Task failed with exception
Traceback (most recent call last):
  File "/home/airflow/.local/lib/python3.7/site-packages/airflow/operators/bash.py", line 197, in execute
    f"Bash command failed. The command returned a non-zero exit code {result.exit_code}."
airflow.exceptions.AirflowException: Bash command failed. The command returned a non-zero exit code 2.
[2022-12-25T04:10:08.075+0000] {taskinstance.py:1327} INFO - Marking task as UP_FOR_RETRY. dag_id=test_etl_deps, task_id=etl_test, execution_date=20221225T040803, start_date=20221225T041007, end_date=20221225T041008
[2022-12-25T04:10:08.096+0000] {standard_task_runner.py:105} ERROR - Failed to execute job 92 for task etl_test (Bash command failed. The command returned a non-zero exit code 2.; 936)
[2022-12-25T04:10:08.124+0000] {local_task_job.py:159} INFO - Task exited with return code 1
[2022-12-25T04:10:08.149+0000] {taskinstance.py:2582} INFO - 0 downstream tasks scheduled from follow-on schedule check
