[2022-12-25T04:40:51.738+0000] {taskinstance.py:1087} INFO - Dependencies all met for <TaskInstance: test_etl_deps.py_test manual__2022-12-25T04:36:40.330152+00:00 [queued]>
[2022-12-25T04:40:51.756+0000] {taskinstance.py:1087} INFO - Dependencies all met for <TaskInstance: test_etl_deps.py_test manual__2022-12-25T04:36:40.330152+00:00 [queued]>
[2022-12-25T04:40:51.758+0000] {taskinstance.py:1283} INFO - 
--------------------------------------------------------------------------------
[2022-12-25T04:40:51.761+0000] {taskinstance.py:1284} INFO - Starting attempt 3 of 6
[2022-12-25T04:40:51.764+0000] {taskinstance.py:1285} INFO - 
--------------------------------------------------------------------------------
[2022-12-25T04:40:51.793+0000] {taskinstance.py:1304} INFO - Executing <Task(BashOperator): py_test> on 2022-12-25 04:36:40.330152+00:00
[2022-12-25T04:40:51.804+0000] {standard_task_runner.py:55} INFO - Started process 2988 to run task
[2022-12-25T04:40:51.812+0000] {standard_task_runner.py:82} INFO - Running: ['***', 'tasks', 'run', 'test_etl_deps', 'py_test', 'manual__2022-12-25T04:36:40.330152+00:00', '--job-id', '154', '--raw', '--subdir', 'DAGS_FOLDER/test_etl_deps.py', '--cfg-path', '/tmp/tmpf7i7utk0']
[2022-12-25T04:40:51.815+0000] {standard_task_runner.py:83} INFO - Job 154: Subtask py_test
[2022-12-25T04:40:51.984+0000] {task_command.py:389} INFO - Running <TaskInstance: test_etl_deps.py_test manual__2022-12-25T04:36:40.330152+00:00 [running]> on host 176142c05a95
[2022-12-25T04:40:52.314+0000] {taskinstance.py:1513} INFO - Exporting the following env vars:
AIRFLOW_CTX_DAG_OWNER=kelompok2
AIRFLOW_CTX_DAG_ID=test_etl_deps
AIRFLOW_CTX_TASK_ID=py_test
AIRFLOW_CTX_EXECUTION_DATE=2022-12-25T04:36:40.330152+00:00
AIRFLOW_CTX_TRY_NUMBER=3
AIRFLOW_CTX_DAG_RUN_ID=manual__2022-12-25T04:36:40.330152+00:00
[2022-12-25T04:40:52.354+0000] {subprocess.py:63} INFO - Tmp dir root location: 
 /tmp
[2022-12-25T04:40:52.359+0000] {subprocess.py:75} INFO - Running command: ['/bin/bash', '-c', 'python3 scripts/consumer.py']
[2022-12-25T04:40:52.420+0000] {subprocess.py:86} INFO - Output:
[2022-12-25T04:40:53.093+0000] {subprocess.py:93} INFO - python3: can't open file 'scripts/consumer.py': [Errno 2] No such file or directory
[2022-12-25T04:40:53.114+0000] {subprocess.py:97} INFO - Command exited with return code 2
[2022-12-25T04:40:53.204+0000] {taskinstance.py:1772} ERROR - Task failed with exception
Traceback (most recent call last):
  File "/home/airflow/.local/lib/python3.7/site-packages/airflow/operators/bash.py", line 197, in execute
    f"Bash command failed. The command returned a non-zero exit code {result.exit_code}."
airflow.exceptions.AirflowException: Bash command failed. The command returned a non-zero exit code 2.
[2022-12-25T04:40:53.223+0000] {taskinstance.py:1327} INFO - Marking task as UP_FOR_RETRY. dag_id=test_etl_deps, task_id=py_test, execution_date=20221225T043640, start_date=20221225T044051, end_date=20221225T044053
[2022-12-25T04:40:53.283+0000] {standard_task_runner.py:105} ERROR - Failed to execute job 154 for task py_test (Bash command failed. The command returned a non-zero exit code 2.; 2988)
[2022-12-25T04:40:53.364+0000] {local_task_job.py:159} INFO - Task exited with return code 1
[2022-12-25T04:40:53.478+0000] {taskinstance.py:2582} INFO - 0 downstream tasks scheduled from follow-on schedule check
