[2022-12-25T04:46:59.268+0000] {taskinstance.py:1087} INFO - Dependencies all met for <TaskInstance: test_etl_deps.py_test manual__2022-12-25T04:36:40.330152+00:00 [queued]>
[2022-12-25T04:46:59.283+0000] {taskinstance.py:1087} INFO - Dependencies all met for <TaskInstance: test_etl_deps.py_test manual__2022-12-25T04:36:40.330152+00:00 [queued]>
[2022-12-25T04:46:59.285+0000] {taskinstance.py:1283} INFO - 
--------------------------------------------------------------------------------
[2022-12-25T04:46:59.287+0000] {taskinstance.py:1284} INFO - Starting attempt 6 of 6
[2022-12-25T04:46:59.289+0000] {taskinstance.py:1285} INFO - 
--------------------------------------------------------------------------------
[2022-12-25T04:46:59.309+0000] {taskinstance.py:1304} INFO - Executing <Task(BashOperator): py_test> on 2022-12-25 04:36:40.330152+00:00
[2022-12-25T04:46:59.319+0000] {standard_task_runner.py:55} INFO - Started process 3402 to run task
[2022-12-25T04:46:59.326+0000] {standard_task_runner.py:82} INFO - Running: ['***', 'tasks', 'run', 'test_etl_deps', 'py_test', 'manual__2022-12-25T04:36:40.330152+00:00', '--job-id', '169', '--raw', '--subdir', 'DAGS_FOLDER/test_etl_deps.py', '--cfg-path', '/tmp/tmp3__s7ewf']
[2022-12-25T04:46:59.331+0000] {standard_task_runner.py:83} INFO - Job 169: Subtask py_test
[2022-12-25T04:46:59.446+0000] {task_command.py:389} INFO - Running <TaskInstance: test_etl_deps.py_test manual__2022-12-25T04:36:40.330152+00:00 [running]> on host 176142c05a95
[2022-12-25T04:46:59.560+0000] {taskinstance.py:1513} INFO - Exporting the following env vars:
AIRFLOW_CTX_DAG_OWNER=kelompok2
AIRFLOW_CTX_DAG_ID=test_etl_deps
AIRFLOW_CTX_TASK_ID=py_test
AIRFLOW_CTX_EXECUTION_DATE=2022-12-25T04:36:40.330152+00:00
AIRFLOW_CTX_TRY_NUMBER=6
AIRFLOW_CTX_DAG_RUN_ID=manual__2022-12-25T04:36:40.330152+00:00
[2022-12-25T04:46:59.565+0000] {subprocess.py:63} INFO - Tmp dir root location: 
 /tmp
[2022-12-25T04:46:59.568+0000] {subprocess.py:75} INFO - Running command: ['/bin/bash', '-c', 'python3 scripts/consumer.py']
[2022-12-25T04:46:59.590+0000] {subprocess.py:86} INFO - Output:
[2022-12-25T04:46:59.741+0000] {subprocess.py:93} INFO - python3: can't open file 'scripts/consumer.py': [Errno 2] No such file or directory
[2022-12-25T04:46:59.748+0000] {subprocess.py:97} INFO - Command exited with return code 2
[2022-12-25T04:46:59.780+0000] {taskinstance.py:1772} ERROR - Task failed with exception
Traceback (most recent call last):
  File "/home/airflow/.local/lib/python3.7/site-packages/airflow/operators/bash.py", line 197, in execute
    f"Bash command failed. The command returned a non-zero exit code {result.exit_code}."
airflow.exceptions.AirflowException: Bash command failed. The command returned a non-zero exit code 2.
[2022-12-25T04:46:59.788+0000] {taskinstance.py:1327} INFO - Marking task as FAILED. dag_id=test_etl_deps, task_id=py_test, execution_date=20221225T043640, start_date=20221225T044659, end_date=20221225T044659
[2022-12-25T04:46:59.814+0000] {standard_task_runner.py:105} ERROR - Failed to execute job 169 for task py_test (Bash command failed. The command returned a non-zero exit code 2.; 3402)
[2022-12-25T04:46:59.862+0000] {local_task_job.py:159} INFO - Task exited with return code 1
[2022-12-25T04:46:59.891+0000] {taskinstance.py:2582} INFO - 0 downstream tasks scheduled from follow-on schedule check
