[2022-12-25T04:27:46.834+0000] {taskinstance.py:1087} INFO - Dependencies all met for <TaskInstance: test_etl_deps.etl_test manual__2022-12-25T04:17:34.058557+00:00 [queued]>
[2022-12-25T04:27:46.880+0000] {taskinstance.py:1087} INFO - Dependencies all met for <TaskInstance: test_etl_deps.etl_test manual__2022-12-25T04:17:34.058557+00:00 [queued]>
[2022-12-25T04:27:46.883+0000] {taskinstance.py:1283} INFO - 
--------------------------------------------------------------------------------
[2022-12-25T04:27:46.885+0000] {taskinstance.py:1284} INFO - Starting attempt 6 of 6
[2022-12-25T04:27:46.887+0000] {taskinstance.py:1285} INFO - 
--------------------------------------------------------------------------------
[2022-12-25T04:27:46.901+0000] {taskinstance.py:1304} INFO - Executing <Task(BashOperator): etl_test> on 2022-12-25 04:17:34.058557+00:00
[2022-12-25T04:27:46.907+0000] {standard_task_runner.py:55} INFO - Started process 2139 to run task
[2022-12-25T04:27:46.912+0000] {standard_task_runner.py:82} INFO - Running: ['***', 'tasks', 'run', 'test_etl_deps', 'etl_test', 'manual__2022-12-25T04:17:34.058557+00:00', '--job-id', '128', '--raw', '--subdir', 'DAGS_FOLDER/test_etl_deps.py', '--cfg-path', '/tmp/tmpao12psj5']
[2022-12-25T04:27:46.914+0000] {standard_task_runner.py:83} INFO - Job 128: Subtask etl_test
[2022-12-25T04:27:46.976+0000] {task_command.py:389} INFO - Running <TaskInstance: test_etl_deps.etl_test manual__2022-12-25T04:17:34.058557+00:00 [running]> on host 176142c05a95
[2022-12-25T04:27:47.034+0000] {taskinstance.py:1513} INFO - Exporting the following env vars:
AIRFLOW_CTX_DAG_OWNER=kelompok2
AIRFLOW_CTX_DAG_ID=test_etl_deps
AIRFLOW_CTX_TASK_ID=etl_test
AIRFLOW_CTX_EXECUTION_DATE=2022-12-25T04:17:34.058557+00:00
AIRFLOW_CTX_TRY_NUMBER=6
AIRFLOW_CTX_DAG_RUN_ID=manual__2022-12-25T04:17:34.058557+00:00
[2022-12-25T04:27:47.037+0000] {subprocess.py:63} INFO - Tmp dir root location: 
 /tmp
[2022-12-25T04:27:47.039+0000] {subprocess.py:75} INFO - Running command: ['/bin/bash', '-c', 'python consumer.py']
[2022-12-25T04:27:47.051+0000] {subprocess.py:86} INFO - Output:
[2022-12-25T04:27:47.133+0000] {subprocess.py:93} INFO - python: can't open file 'consumer.py': [Errno 2] No such file or directory
[2022-12-25T04:27:47.137+0000] {subprocess.py:97} INFO - Command exited with return code 2
[2022-12-25T04:27:47.150+0000] {taskinstance.py:1772} ERROR - Task failed with exception
Traceback (most recent call last):
  File "/home/airflow/.local/lib/python3.7/site-packages/airflow/operators/bash.py", line 197, in execute
    f"Bash command failed. The command returned a non-zero exit code {result.exit_code}."
airflow.exceptions.AirflowException: Bash command failed. The command returned a non-zero exit code 2.
[2022-12-25T04:27:47.155+0000] {taskinstance.py:1327} INFO - Marking task as FAILED. dag_id=test_etl_deps, task_id=etl_test, execution_date=20221225T041734, start_date=20221225T042746, end_date=20221225T042747
[2022-12-25T04:27:47.168+0000] {standard_task_runner.py:105} ERROR - Failed to execute job 128 for task etl_test (Bash command failed. The command returned a non-zero exit code 2.; 2139)
[2022-12-25T04:27:47.205+0000] {local_task_job.py:159} INFO - Task exited with return code 1
[2022-12-25T04:27:47.234+0000] {taskinstance.py:2582} INFO - 0 downstream tasks scheduled from follow-on schedule check
