[2022-12-25T04:23:43.630+0000] {taskinstance.py:1087} INFO - Dependencies all met for <TaskInstance: test_etl_deps.etl_test manual__2022-12-25T04:17:34.058557+00:00 [queued]>
[2022-12-25T04:23:43.648+0000] {taskinstance.py:1087} INFO - Dependencies all met for <TaskInstance: test_etl_deps.etl_test manual__2022-12-25T04:17:34.058557+00:00 [queued]>
[2022-12-25T04:23:43.650+0000] {taskinstance.py:1283} INFO - 
--------------------------------------------------------------------------------
[2022-12-25T04:23:43.653+0000] {taskinstance.py:1284} INFO - Starting attempt 4 of 6
[2022-12-25T04:23:43.654+0000] {taskinstance.py:1285} INFO - 
--------------------------------------------------------------------------------
[2022-12-25T04:23:43.688+0000] {taskinstance.py:1304} INFO - Executing <Task(BashOperator): etl_test> on 2022-12-25 04:17:34.058557+00:00
[2022-12-25T04:23:43.702+0000] {standard_task_runner.py:55} INFO - Started process 1854 to run task
[2022-12-25T04:23:43.709+0000] {standard_task_runner.py:82} INFO - Running: ['***', 'tasks', 'run', 'test_etl_deps', 'etl_test', 'manual__2022-12-25T04:17:34.058557+00:00', '--job-id', '120', '--raw', '--subdir', 'DAGS_FOLDER/test_etl_deps.py', '--cfg-path', '/tmp/tmp6vb0kv_f']
[2022-12-25T04:23:43.711+0000] {standard_task_runner.py:83} INFO - Job 120: Subtask etl_test
[2022-12-25T04:23:43.931+0000] {task_command.py:389} INFO - Running <TaskInstance: test_etl_deps.etl_test manual__2022-12-25T04:17:34.058557+00:00 [running]> on host 176142c05a95
[2022-12-25T04:23:44.103+0000] {taskinstance.py:1513} INFO - Exporting the following env vars:
AIRFLOW_CTX_DAG_OWNER=kelompok2
AIRFLOW_CTX_DAG_ID=test_etl_deps
AIRFLOW_CTX_TASK_ID=etl_test
AIRFLOW_CTX_EXECUTION_DATE=2022-12-25T04:17:34.058557+00:00
AIRFLOW_CTX_TRY_NUMBER=4
AIRFLOW_CTX_DAG_RUN_ID=manual__2022-12-25T04:17:34.058557+00:00
[2022-12-25T04:23:44.114+0000] {subprocess.py:63} INFO - Tmp dir root location: 
 /tmp
[2022-12-25T04:23:44.119+0000] {subprocess.py:75} INFO - Running command: ['/bin/bash', '-c', 'python consumer.py']
[2022-12-25T04:23:44.149+0000] {subprocess.py:86} INFO - Output:
[2022-12-25T04:23:44.410+0000] {subprocess.py:93} INFO - python: can't open file 'consumer.py': [Errno 2] No such file or directory
[2022-12-25T04:23:44.421+0000] {subprocess.py:97} INFO - Command exited with return code 2
[2022-12-25T04:23:44.454+0000] {taskinstance.py:1772} ERROR - Task failed with exception
Traceback (most recent call last):
  File "/home/airflow/.local/lib/python3.7/site-packages/airflow/operators/bash.py", line 197, in execute
    f"Bash command failed. The command returned a non-zero exit code {result.exit_code}."
airflow.exceptions.AirflowException: Bash command failed. The command returned a non-zero exit code 2.
[2022-12-25T04:23:44.468+0000] {taskinstance.py:1327} INFO - Marking task as UP_FOR_RETRY. dag_id=test_etl_deps, task_id=etl_test, execution_date=20221225T041734, start_date=20221225T042343, end_date=20221225T042344
[2022-12-25T04:23:44.501+0000] {standard_task_runner.py:105} ERROR - Failed to execute job 120 for task etl_test (Bash command failed. The command returned a non-zero exit code 2.; 1854)
[2022-12-25T04:23:44.528+0000] {local_task_job.py:159} INFO - Task exited with return code 1
[2022-12-25T04:23:44.566+0000] {taskinstance.py:2582} INFO - 0 downstream tasks scheduled from follow-on schedule check
