[2022-12-25T04:19:38.990+0000] {taskinstance.py:1087} INFO - Dependencies all met for <TaskInstance: test_etl_deps.etl_test manual__2022-12-25T04:17:34.058557+00:00 [queued]>
[2022-12-25T04:19:39.016+0000] {taskinstance.py:1087} INFO - Dependencies all met for <TaskInstance: test_etl_deps.etl_test manual__2022-12-25T04:17:34.058557+00:00 [queued]>
[2022-12-25T04:19:39.022+0000] {taskinstance.py:1283} INFO - 
--------------------------------------------------------------------------------
[2022-12-25T04:19:39.024+0000] {taskinstance.py:1284} INFO - Starting attempt 2 of 6
[2022-12-25T04:19:39.029+0000] {taskinstance.py:1285} INFO - 
--------------------------------------------------------------------------------
[2022-12-25T04:19:39.064+0000] {taskinstance.py:1304} INFO - Executing <Task(BashOperator): etl_test> on 2022-12-25 04:17:34.058557+00:00
[2022-12-25T04:19:39.080+0000] {standard_task_runner.py:55} INFO - Started process 1583 to run task
[2022-12-25T04:19:39.116+0000] {standard_task_runner.py:82} INFO - Running: ['***', 'tasks', 'run', 'test_etl_deps', 'etl_test', 'manual__2022-12-25T04:17:34.058557+00:00', '--job-id', '111', '--raw', '--subdir', 'DAGS_FOLDER/test_etl_deps.py', '--cfg-path', '/tmp/tmpifmj4r_j']
[2022-12-25T04:19:39.120+0000] {standard_task_runner.py:83} INFO - Job 111: Subtask etl_test
[2022-12-25T04:19:39.350+0000] {task_command.py:389} INFO - Running <TaskInstance: test_etl_deps.etl_test manual__2022-12-25T04:17:34.058557+00:00 [running]> on host 176142c05a95
[2022-12-25T04:19:39.564+0000] {taskinstance.py:1513} INFO - Exporting the following env vars:
AIRFLOW_CTX_DAG_OWNER=kelompok2
AIRFLOW_CTX_DAG_ID=test_etl_deps
AIRFLOW_CTX_TASK_ID=etl_test
AIRFLOW_CTX_EXECUTION_DATE=2022-12-25T04:17:34.058557+00:00
AIRFLOW_CTX_TRY_NUMBER=2
AIRFLOW_CTX_DAG_RUN_ID=manual__2022-12-25T04:17:34.058557+00:00
[2022-12-25T04:19:39.584+0000] {subprocess.py:63} INFO - Tmp dir root location: 
 /tmp
[2022-12-25T04:19:39.593+0000] {subprocess.py:75} INFO - Running command: ['/bin/bash', '-c', 'python ~/scripts/consumer.py']
[2022-12-25T04:19:39.627+0000] {subprocess.py:86} INFO - Output:
[2022-12-25T04:19:39.859+0000] {subprocess.py:93} INFO - python: can't open file '/home/***/scripts/consumer.py': [Errno 2] No such file or directory
[2022-12-25T04:19:39.874+0000] {subprocess.py:97} INFO - Command exited with return code 2
[2022-12-25T04:19:39.898+0000] {taskinstance.py:1772} ERROR - Task failed with exception
Traceback (most recent call last):
  File "/home/airflow/.local/lib/python3.7/site-packages/airflow/operators/bash.py", line 197, in execute
    f"Bash command failed. The command returned a non-zero exit code {result.exit_code}."
airflow.exceptions.AirflowException: Bash command failed. The command returned a non-zero exit code 2.
[2022-12-25T04:19:39.908+0000] {taskinstance.py:1327} INFO - Marking task as UP_FOR_RETRY. dag_id=test_etl_deps, task_id=etl_test, execution_date=20221225T041734, start_date=20221225T041938, end_date=20221225T041939
[2022-12-25T04:19:39.941+0000] {standard_task_runner.py:105} ERROR - Failed to execute job 111 for task etl_test (Bash command failed. The command returned a non-zero exit code 2.; 1583)
[2022-12-25T04:19:39.970+0000] {local_task_job.py:159} INFO - Task exited with return code 1
[2022-12-25T04:19:40.016+0000] {taskinstance.py:2582} INFO - 0 downstream tasks scheduled from follow-on schedule check
